Workbook
Name 机箱: '数据库（价格维护）'!$I:$I
Name 内存: '数据库（价格维护）'!#REF!
Name 显卡: '数据库（价格维护）'!$M:$M
Name 显示器: '数据库（价格维护）'!$A:$A
Name 音频系统: '数据库（价格维护）'!$Q:$Q
Name LED屏: '数据库（价格维护）'!$C:$C
Name 投影机: '数据库（价格维护）'!$E:$E
Name 互动方式: '数据库（价格维护）'!$G:$G
Name 处理器: '数据库（价格维护）'!$K:$K
Name 硬盘: '数据库（价格维护）'!#REF!
Name 传输方式: '数据库（价格维护）'!$O:$O
Name 辅材: '数据库（价格维护）'!$S:$S
Name 一: '数据库（价格维护）'!$U:$U
Name 二: '数据库（价格维护）'!$W:$W
Name 三: '数据库（价格维护）'!$Y:$Y
Name 四: '数据库（价格维护）'!$AA:$AA
Name 五: '数据库（价格维护）'!$AC:$AC
Name 六: '数据库（价格维护）'!$AE:$AE
Name 七: '数据库（价格维护）'!$AG:$AG
Name 八: '数据库（价格维护）'!$AI:$AI
Name 九: '数据库（价格维护）'!$AK:$AK
Name 十: '数据库（价格维护）'!$AM:$AM
Name 十一: '数据库（价格维护）'!$AO:$AO
Name 十二: '数据库（价格维护）'!$AQ:$AQ
Name 十三: '数据库（价格维护）'!$AS:$AS
Name 十四: '数据库（价格维护）'!$AU:$AU
Name 十五: '数据库（价格维护）'!$AW:$AW
Name 十六: '数据库（价格维护）'!$AY:$AY
Name 十七: '数据库（价格维护）'!$BA:$BA

Sheet 报价单
B2: ="多媒体展项报价"&TEXT(NOW()," yyyy年mm月dd日 hh:mm:ss") -> 多媒体展项报价 2026年09月10日 18:07:17
B3: 配件名称 | C3: 规格 | D3: 单价 | E3: 数量 | F3: 合计 | H3: 备注
B4: 显示器 | C4: 10.1 英寸 比例：16:10 分辨率：1280×800 可视区域：218×136 mm 整机尺寸：240×150×20 mm 重量：0.6–0.8 kg 功率：10–15 W 亮度：400–500 cd/㎡ 对比度：1000:1 | D4: =IFERROR(VLOOKUP(C4,'数据库（价格维护）'!A:ZV,2,0),0) -> 800 | E4: 1 | F4: =D4*E4 -> 800
B5: LED屏 | D5: =IFERROR(VLOOKUP(C5,'数据库（价格维护）'!C:ZV,2,0),0) -> 0 | E5: 1 | F5: =D5*E5 -> 0
B6: 投影机 | D6: =IFERROR(VLOOKUP(C6,'数据库（价格维护）'!E:ZV,2,0),0) -> 0 | E6: 1 | F6: =D6*E6 -> 0
B7: 互动方式 | D7: =IFERROR(VLOOKUP(C7,'数据库（价格维护）'!G:ZV,2,0),0) -> 0 | E7: 1 | F7: =D7*E7 -> 0
B8: 机箱 | D8: =IFERROR(VLOOKUP(C8,'数据库（价格维护）'!I:ZV,2,0),0) -> 0 | E8: 1 | F8: =D8*E8 -> 0
B9: 主板 | D9: =IFERROR(VLOOKUP(C9,'数据库（价格维护）'!K:ZV,2,0),0) -> 0 | E9: 1 | F9: =D9*E9 -> 0
B10: 显卡 | D10: =IFERROR(VLOOKUP(C10,'数据库（价格维护）'!M:ZV,2,0),0) -> 0 | E10: 1 | F10: =D10*E10 -> 0
B11: 传输方式 | D11: =IFERROR(VLOOKUP(C11,'数据库（价格维护）'!O:ZV,2,0),0) -> 0 | E11: 1 | F11: =D11*E11 -> 0
B12: 音频系统 | D12: =IFERROR(VLOOKUP(C12,'数据库（价格维护）'!Q:ZV,2,0),0) -> 0 | E12: 1 | F12: =D12*E12 -> 0
B13: 辅材 | D13: =IFERROR(VLOOKUP(C13,'数据库（价格维护）'!S:ZV,2,0),0) -> 0 | E13: 1 | F13: =D13*E13 -> 0
B14: 1 | D14: =IFERROR(VLOOKUP(C14,'数据库（价格维护）'!U:ZV,2,0),0) -> 0 | E14: 1 | F14: =D14*E14 -> 0
B15: 2 | D15: =IFERROR(VLOOKUP(C15,'数据库（价格维护）'!W:ZV,2,0),0) -> 0 | E15: 1 | F15: =D15*E15 -> 0
B16: 3 | D16: =IFERROR(VLOOKUP(C16,'数据库（价格维护）'!Y:ZV,2,0),0) -> 0 | E16: 1 | F16: =D16*E16 -> 0
B17: 4 | D17: =IFERROR(VLOOKUP(C17,'数据库（价格维护）'!AA:ZV,2,0),0) -> 0 | E17: 1 | F17: =D17*E17 -> 0
B18: 影片 | C18: 智慧展馆运维管理程序 功能：客流统计、设备巡检、故障报警、运行日志、远程控制 专业参数：数据采集频率≤5s；支持 Modbus/OpcUa 协议；提供 API 接口与第三方系统对接；支持移动端管理。 | D18: =IFERROR(VLOOKUP(C18,'数据库（价格维护）'!AC:ZV,2,0),0) -> 0 | E18: 1 | F18: =D18*E18 -> 0
B19: 6 | D19: =IFERROR(VLOOKUP(C19,'数据库（价格维护）'!AE:ZV,2,0),0) -> 0 | E19: 1 | F19: =D19*E19 -> 0
B20: 7 | D20: =IFERROR(VLOOKUP(C20,'数据库（价格维护）'!AG:ZV,2,0),0) -> 0 | E20: 1 | F20: =D20*E20 -> 0
B21: 8 | D21: =IFERROR(VLOOKUP(C21,'数据库（价格维护）'!AI:ZV,2,0),0) -> 0 | E21: 1 | F21: =D21*E21 -> 0
B22: 9 | D22: =IFERROR(VLOOKUP(C22,'数据库（价格维护）'!AK:ZV,2,0),0) -> 0 | E22: 1 | F22: =D22*E22 -> 0
B23: 10 | D23: =IFERROR(VLOOKUP(C23,'数据库（价格维护）'!AM:ZV,2,0),0) -> 0 | E23: 1 | F23: =D23*E23 -> 0
B24: 11 | D24: =IFERROR(VLOOKUP(C24,'数据库（价格维护）'!AO:ZV,2,0),0) -> 0 | E24: 1 | F24: =D24*E24 -> 0
B25: 12 | D25: =IFERROR(VLOOKUP(C25,'数据库（价格维护）'!AQ:ZV,2,0),0) -> 0 | E25: 1 | F25: =D25*E25 -> 0
B26: 13 | D26: =IFERROR(VLOOKUP(C26,'数据库（价格维护）'!AS:ZV,2,0),0) -> 0 | E26: 1 | F26: =D26*E26 -> 0
B27: 14 | D27: =IFERROR(VLOOKUP(C27,'数据库（价格维护）'!AU:ZV,2,0),0) -> 0 | E27: 1 | F27: =D27*E27 -> 0
B28: 15 | D28: =IFERROR(VLOOKUP(C28,'数据库（价格维护）'!AW:ZV,2,0),0) -> 0 | E28: 1 | F28: =D28*E28 -> 0
B29: 其它 | D29: 0 | E29: 1 | F29: =D29*E29 -> 0
B30: 备注
B31: 使用前 更新数据库
B32: 生成参数： | C32: =_xlfn.TEXTJOIN("",TRUE,C4:C28) -> 10.1 英寸 比例：16:10 分辨率：1280×800 可视区域：218×136 mm 整机尺寸：240×150×20 mm 重量：0.6–0.8 kg 功率：10–15 W 亮度：400–500 cd/㎡ 对比度：1000:1智慧展馆运维管理程序 功能：客流统计、设备巡检、故障报警、运行日志、远程控制 专业参数：数据采集频率≤5s；支持 Modbus/OpcUa 协议；提供 API 接口与第三方系统对接；支持移动端管理。 | D32: 税点 | F32: 0 | G32: =SUM(F4:G29)*F32 -> 0
B33: 金额 | C33: =IF(F34=0,"",IF(F34>=10000,INT(F34/10000)&"万"&MOD(F34,10000),F34)) -> 800 | D33: 利润 | F33: 0 | G33: =SUM(F4:G29)*F33 -> 0
D34: 总价 | F34: =SUM(F4:G29)+G32+G33 -> 800
B35: 计算器 | C35: https://4kwjstdndc4ww.aiforce.cloud/app/app_17dv0xu8t0y

Sheet 数据库（价格维护）
A1: 显示器 | B1: 显示器价格 | C1: LED屏 | D1: LED屏价格 | E1: 投影机 | F1: 投影机价格 | G1: 互动方式 | H1: 互动方式价格 | I1: 机箱 | J1: 机箱价格 | K1: 主板 | L1: 配置价格 | M1: 显卡 | N1: 显卡价格 | O1: 传输方式 | P1: 传输方式价格 | Q1: 音频系统 | R1: 音频系统价格 | S1: 辅材 | T1: 辅材价格 | U1: LED主控器 | V1: 产品价格 | W1: 二 | X1: 产品价格 | Y1: 三 | Z1: 产品价格 | AA1: 影片 | AB1: 产品价格 | AC1: 程序 | AD1: 产品价格 | AE1: 六 | AF1: 产品价格 | AG1: 七 | AH1: 产品价格 | AI1: 八 | AJ1: 产品价格 | AK1: 九 | AL1: 产品价格 | AM1: 十 | AN1: 产品价格 | AO1: 十一 | AP1: 产品价格 | AQ1: 十二 | AR1: 产品价格 | AS1: 十三 | AT1: 产品价格 | AU1: 十四 | AV1: 产品价格 | AW1: 十五 | AX1: 产品价格 | AY1: 十六 | AZ1: 产品价格 | BA1: 十七 | BB1: 产品价格 | BC1: 十八 | BD1: 产品价格 | BE1: 十九 | BF1: 产品价格 | BG1: 二十 | BH1: 产品价格 | BI1: 二十一 | BJ1: 产品价格 | BK1: 二十二 | BL1: 产品价格 | BM1: 二十三 | BN1: 产品价格 | BO1: 二十四 | BP1: 产品价格 | BQ1: 二十五 | BR1: 产品价格 | BS1: 二十六 | BT1: 产品价格 | BU1: 二十七 | BV1: 产品价格 | BW1: 二十八 | BX1: 产品价格 | BY1: 二十九 | BZ1: 产品价格 | CA1: 三十 | CB1: 产品价格 | CC1: 三十一 | CD1: 产品价格 | CE1: 三十二 | CF1: 产品价格 | CG1: 三十三 | CH1: 产品价格 | CI1: 三十四 | CJ1: 产品价格 | CK1: 6 | CL1: 产品价格 | CM1: 7 | CN1: 产品价格 | CO1: 7 | CP1: 产品价格 | CQ1: 8 | CR1: 产品价格 | CS1: 8 | CT1: 产品价格 | CU1: 9 | CV1: 产品价格 | CW1: 9 | CX1: 产品价格 | CY1: 10 | CZ1: 产品价格 | DA1: 4 | DB1: 产品价格 | DC1: 5 | DD1: 产品价格 | DE1: 5 | DF1: 产品价格 | DG1: 6 | DH1: 产品价格 | DI1: 6 | DJ1: 产品价格 | DK1: 7 | DL1: 产品价格 | DM1: 7 | DN1: 产品价格 | DO1: 8 | DP1: 产品价格 | DQ1: 8 | DR1: 产品价格 | DS1: 9 | DT1: 产品价格 | DU1: 9 | DV1: 产品价格 | DW1: 10 | DX1: 产品价格 | DY1: 10 | DZ1: 产品价格 | EA1: 11 | EB1: 产品价格 | EC1: 5 | ED1: 产品价格 | EE1: 6 | EF1: 产品价格 | EG1: 6 | EH1: 产品价格 | EI1: 7 | EJ1: 产品价格 | EK1: 7 | EL1: 产品价格 | EM1: 8 | EN1: 产品价格 | EO1: 8 | EP1: 产品价格 | EQ1: 9 | ER1: 产品价格 | ES1: 9 | ET1: 产品价格 | EU1: 10 | EV1: 产品价格 | EW1: 10 | EX1: 产品价格 | EY1: 11 | EZ1: 产品价格 | FA1: 11 | FB1: 产品价格 | FC1: 12 | FD1: 产品价格 | FE1: 6 | FF1: 产品价格 | FG1: 7 | FH1: 产品价格 | FI1: 7 | FJ1: 产品价格 | FK1: 8 | FL1: 产品价格 | FM1: 8 | FN1: 产品价格 | FO1: 9 | FP1: 产品价格 | FQ1: 9 | FR1: 产品价格 | FS1: 10 | FT1: 产品价格 | FU1: 10 | FV1: 产品价格 | FW1: 11 | FX1: 产品价格 | FY1: 11 | FZ1: 产品价格 | GA1: 12 | GB1: 产品价格 | GC1: 12 | GD1: 产品价格 | GE1: 13 | GF1: 产品价格 | GG1: 7 | GH1: 产品价格 | GI1: 8 | GJ1: 产品价格 | GK1: 8 | GL1: 产品价格 | GM1: 9 | GN1: 产品价格 | GO1: 9 | GP1: 产品价格 | GQ1: 10 | GR1: 产品价格 | GS1: 10 | GT1: 产品价格 | GU1: 11 | GV1: 产品价格 | GW1: 11 | GX1: 产品价格 | GY1: 12 | GZ1: 产品价格 | HA1: 12 | HB1: 产品价格 | HC1: 13 | HD1: 产品价格 | HE1: 13 | HF1: 产品价格 | HG1: 14 | HH1: 产品价格 | HI1: 8 | HJ1: 产品价格 | HK1: 9 | HL1: 产品价格 | HM1: 9 | HN1: 产品价格 | HO1: 10 | HP1: 产品价格 | HQ1: 10 | HR1: 产品价格 | HS1: 11 | HT1: 产品价格 | HU1: 11 | HV1: 产品价格 | HW1: 12 | HX1: 产品价格 | HY1: 12 | HZ1: 产品价格 | IA1: 13 | IB1: 产品价格 | IC1: 13 | ID1: 产品价格 | IE1: 14 | IF1: 产品价格 | IG1: 14 | IH1: 产品价格 | II1: 15 | IJ1: 产品价格 | IK1: 9 | IL1: 产品价格 | IM1: 10 | IN1: 产品价格 | IO1: 10 | IP1: 产品价格 | IQ1: 11 | IR1: 产品价格 | IS1: 11 | IT1: 产品价格 | IU1: 12 | IV1: 产品价格 | IW1: 12 | IX1: 产品价格 | IY1: 13 | IZ1: 产品价格 | JA1: 13 | JB1: 产品价格 | JC1: 14 | JD1: 产品价格 | JE1: 14 | JF1: 产品价格 | JG1: 15 | JH1: 产品价格 | JI1: 15 | JJ1: 产品价格 | JK1: 16 | JL1: 产品价格 | JM1: 10 | JN1: 产品价格 | JO1: 11 | JP1: 产品价格 | JQ1: 11 | JR1: 产品价格 | JS1: 12 | JT1: 产品价格 | JU1: 12 | JV1: 产品价格 | JW1: 13 | JX1: 产品价格 | JY1: 13 | JZ1: 产品价格 | KA1: 14 | KB1: 产品价格 | KC1: 14 | KD1: 产品价格 | KE1: 15 | KF1: 产品价格 | KG1: 15 | KH1: 产品价格 | KI1: 16 | KJ1: 产品价格 | KK1: 16 | KL1: 产品价格 | KM1: 17 | KN1: 产品价格 | KO1: 11 | KP1: 产品价格 | KQ1: 12 | KR1: 产品价格 | KS1: 12 | KT1: 产品价格 | KU1: 13 | KV1: 产品价格 | KW1: 13 | KX1: 产品价格 | KY1: 14 | KZ1: 产品价格 | LA1: 14 | LB1: 产品价格 | LC1: 15 | LD1: 产品价格 | LE1: 15 | LF1: 产品价格 | LG1: 16 | LH1: 产品价格 | LI1: 16 | LJ1: 产品价格 | LK1: 17 | LL1: 产品价格 | LM1: 17 | LN1: 产品价格 | LO1: 18 | LP1: 产品价格 | LQ1: 12 | LR1: 产品价格 | LS1: 13 | LT1: 产品价格 | LU1: 13 | LV1: 产品价格 | LW1: 14 | LX1: 产品价格 | LY1: 14 | LZ1: 产品价格 | MA1: 15 | MB1: 产品价格 | MC1: 15 | MD1: 产品价格 | ME1: 16 | MF1: 产品价格 | MG1: 16 | MH1: 产品价格 | MI1: 17 | MJ1: 产品价格 | MK1: 17 | ML1: 产品价格 | MM1: 18 | MN1: 产品价格 | MO1: 18 | MP1: 产品价格 | MQ1: 19 | MR1: 产品价格 | MS1: 13 | MT1: 产品价格 | MU1: 14 | MV1: 产品价格 | MW1: 14 | MX1: 产品价格 | MY1: 15 | MZ1: 产品价格 | NA1: 15 | NB1: 产品价格 | NC1: 16 | ND1: 产品价格 | NE1: 16 | NF1: 产品价格 | NG1: 17 | NH1: 产品价格 | NI1: 17 | NJ1: 产品价格 | NK1: 18 | NL1: 产品价格 | NM1: 18 | NN1: 产品价格 | NO1: 19 | NP1: 产品价格 | NQ1: 19 | NR1: 产品价格 | NS1: 20 | NT1: 产品价格 | NU1: 14 | NV1: 产品价格 | NW1: 15 | NX1: 产品价格 | NY1: 15 | NZ1: 产品价格 | OA1: 16 | OB1: 产品价格 | OC1: 16 | OD1: 产品价格 | OE1: 17 | OF1: 产品价格 | OG1: 17 | OH1: 产品价格 | OI1: 18 | OJ1: 产品价格 | OK1: 18 | OL1: 产品价格 | OM1: 19 | ON1: 产品价格 | OO1: 19 | OP1: 产品价格 | OQ1: 20 | OR1: 产品价格 | OS1: 20 | OT1: 产品价格 | OU1: 21 | OV1: 产品价格 | OW1: 15 | OX1: 产品价格 | OY1: 16 | OZ1: 产品价格 | PA1: 16 | PB1: 产品价格 | PC1: 17 | PD1: 产品价格 | PE1: 17 | PF1: 产品价格 | PG1: 18 | PH1: 产品价格 | PI1: 18 | PJ1: 产品价格 | PK1: 19 | PL1: 产品价格 | PM1: 19 | PN1: 产品价格 | PO1: 20 | PP1: 产品价格 | PQ1: 20 | PR1: 产品价格 | PS1: 21 | PT1: 产品价格 | PU1: 21 | PV1: 产品价格 | PW1: 22 | PX1: 产品价格 | PY1: 16 | PZ1: 产品价格 | QA1: 17 | QB1: 产品价格 | QC1: 17 | QD1: 产品价格 | QE1: 18 | QF1: 产品价格 | QG1: 18 | QH1: 产品价格 | QI1: 19 | QJ1: 产品价格 | QK1: 19 | QL1: 产品价格 | QM1: 20 | QN1: 产品价格 | QO1: 20 | QP1: 产品价格 | QQ1: 21 | QR1: 产品价格 | QS1: 21 | QT1: 产品价格 | QU1: 22 | QV1: 产品价格 | QW1: 22 | QX1: 产品价格 | QY1: 23 | QZ1: 产品价格 | RA1: 17 | RB1: 产品价格 | RC1: 18 | RD1: 产品价格 | RE1: 18 | RF1: 产品价格 | RG1: 19 | RH1: 产品价格 | RI1: 19 | RJ1: 产品价格 | RK1: 20 | RL1: 产品价格 | RM1: 20 | RN1: 产品价格 | RO1: 21 | RP1: 产品价格 | RQ1: 21 | RR1: 产品价格 | RS1: 22 | RT1: 产品价格 | RU1: 22 | RV1: 产品价格 | RW1: 23 | RX1: 产品价格 | RY1: 23 | RZ1: 产品价格 | SA1: 24 | SB1: 产品价格 | SC1: 18 | SD1: 产品价格 | SE1: 19 | SF1: 产品价格 | SG1: 19 | SH1: 产品价格 | SI1: 20 | SJ1: 产品价格 | SK1: 20 | SL1: 产品价格 | SM1: 21 | SN1: 产品价格 | SO1: 21 | SP1: 产品价格 | SQ1: 22 | SR1: 产品价格 | SS1: 22 | ST1: 产品价格 | SU1: 23 | SV1: 产品价格 | SW1: 23 | SX1: 产品价格 | SY1: 24 | SZ1: 产品价格 | TA1: 24 | TB1: 产品价格 | TC1: 25 | TD1: 产品价格 | TE1: 19 | TF1: 产品价格 | TG1: 20 | TH1: 产品价格 | TI1: 20 | TJ1: 产品价格 | TK1: 21 | TL1: 产品价格 | TM1: 21 | TN1: 产品价格 | TO1: 22 | TP1: 产品价格 | TQ1: 22 | TR1: 产品价格 | TS1: 23 | TT1: 产品价格 | TU1: 23 | TV1: 产品价格 | TW1: 24 | TX1: 产品价格 | TY1: 24 | TZ1: 产品价格 | UA1: 25 | UB1: 产品价格 | UC1: 25 | UD1: 产品价格 | UE1: 26 | UF1: 产品价格 | UG1: 20 | UH1: 产品价格 | UI1: 21 | UJ1: 产品价格 | UK1: 21 | UL1: 产品价格 | UM1: 22 | UN1: 产品价格 | UO1: 22 | UP1: 产品价格 | UQ1: 23 | UR1: 产品价格 | US1: 23 | UT1: 产品价格 | UU1: 24 | UV1: 产品价格 | UW1: 24 | UX1: 产品价格 | UY1: 25 | UZ1: 产品价格 | VA1: 25 | VB1: 产品价格 | VC1: 26 | VD1: 产品价格 | VE1: 26 | VF1: 产品价格 | VG1: 27 | VH1: 产品价格 | VI1: 21 | VJ1: 产品价格 | VK1: 22 | VL1: 产品价格 | VM1: 22 | VN1: 产品价格 | VO1: 23 | VP1: 产品价格 | VQ1: 23 | VR1: 产品价格 | VS1: 24 | VT1: 产品价格 | VU1: 24 | VV1: 产品价格 | VW1: 25 | VX1: 产品价格 | VY1: 25 | VZ1: 产品价格 | WA1: 26 | WB1: 产品价格 | WC1: 26 | WD1: 产品价格 | WE1: 27 | WF1: 产品价格 | WG1: 27 | WH1: 产品价格 | WI1: 28 | WJ1: 产品价格 | WK1: 22 | WL1: 产品价格 | WM1: 23 | WN1: 产品价格 | WO1: 23 | WP1: 产品价格 | WQ1: 24 | WR1: 产品价格 | WS1: 24 | WT1: 产品价格 | WU1: 25 | WV1: 产品价格 | WW1: 25 | WX1: 产品价格 | WY1: 26 | WZ1: 产品价格 | XA1: 26 | XB1: 产品价格 | XC1: 27 | XD1: 产品价格 | XE1: 27 | XF1: 产品价格 | XG1: 28 | XH1: 产品价格 | XI1: 28 | XJ1: 产品价格 | XK1: 29 | XL1: 产品价格 | XM1: 23 | XN1: 产品价格 | XO1: 24 | XP1: 产品价格 | XQ1: 24 | XR1: 产品价格 | XS1: 25 | XT1: 产品价格 | XU1: 25 | XV1: 产品价格 | XW1: 26 | XX1: 产品价格 | XY1: 26 | XZ1: 产品价格 | YA1: 27 | YB1: 产品价格 | YC1: 27 | YD1: 产品价格 | YE1: 28 | YF1: 产品价格 | YG1: 28 | YH1: 产品价格 | YI1: 29 | YJ1: 产品价格 | YK1: 29 | YL1: 产品价格 | YM1: 30 | YN1: 产品价格 | YO1: 24 | YP1: 产品价格 | YQ1: 25 | YR1: 产品价格 | YS1: 25 | YT1: 产品价格 | YU1: 26 | YV1: 产品价格 | YW1: 26 | YX1: 产品价格 | YY1: 27 | YZ1: 产品价格 | ZA1: 27 | ZB1: 产品价格 | ZC1: 28 | ZD1: 产品价格 | ZE1: 28 | ZF1: 产品价格 | ZG1: 29 | ZH1: 产品价格 | ZI1: 29 | ZJ1: 产品价格 | ZK1: 30 | ZL1: 产品价格 | ZM1: 30 | ZN1: 产品价格 | ZO1: 31 | ZP1: 产品价格 | ZQ1: 25 | ZR1: 产品价格 | ZS1: 26 | ZT1: 产品价格 | ZU1: 26 | ZV1: 产品价格
A2: 10.1 英寸 比例：16:10 分辨率：1280×800 可视区域：218×136 mm 整机尺寸：240×150×20 mm 重量：0.6–0.8 kg 功率：10–15 W 亮度：400–500 cd/㎡ 对比度：1000:1 | B2: 800 | C2: P0.9 Micro LED 基础规格 点间距：0.9375mm 像素密度：1,137,777 dots/㎡ 模组尺寸：300×168.75mm（分辨率320×180） 封装技术：全倒装COB封装，表面防撞耐磨 箱体尺寸：600×337.5mm（标准16:9拼接） 显示性能 亮度：600-800 cd/㎡（支持0-800cd/㎡智能调节） 对比度：≥20,000:1 刷新率：7680Hz 灰度等级：16-20bit 色域：≥95% DCI-P3 可视角度：水平170°/垂直160° 配套适配 电源配置：1㎡配置2台400W/5V冗余电源 接收卡：1㎡配置0.5张高端接收卡（单卡带载≥500万像素） 功耗：最大450W/㎡，平均150W/㎡ 线缆：RVV 3×4mm²主缆+3×2.5mm²分缆，配套抗干扰扁平线 | D2: 80000 | E2: 亮度≥6000 流明（ISO）、1080P 分辨率、≥10000:1 动态对比度，DLP 技术，可换镜头，支持 HDR10+/HLG、≥95% DCI-P3 色域；机身约 520×400×220mm、≤15kg，支持吊装；接口含 HDMI、USB 2.0×2、RJ45 千兆 、RS232、VGA；具备 ±50° 梯校、360° 旋转、边缘融合、几何校正，兼容主流中控，IP54 防护、-15℃-50℃宽温、7×24 小时运行，支持远程监控 ；电源 AC 100-240V（50/60Hz），额定功耗≤400W、待机≤0.5W，带断电记忆。 | F2: 19800 | G2: 电容式多点触摸； | H2: 200 | I2: 内置主板支持网络唤醒定时： | J2: 1000 | K2: CPU:I5八代\内存:8G\硬盘128G； | L2: 2100 | M2: 显卡：核显； | N2: 0 | O2: 视频网传：RJ45 千兆 ，支持 4K@60Hz， H.264/H.265 编码，网线传 100m，级联可延长，延迟 200ms~1s（编码）/<50ms（无压缩），支持多对多传输 | P2: 1400 | Q2: 功放：双通道，8Ω 每路 500W，频响 20Hz-20kHz±0.5dB，失真≤0.05%，信噪比 > 100dB，支持双声道 / 桥接模式。 专业音响（2 只）：8Ω 额定功率 500W，频响 50Hz-20kHz，灵敏度 98dB，全频扬声器单元，支持 Speakon 接口连接。 | R2: 4600 | S2: 网络跳线面板、固定结构、辅助配件、工具耗材 | T2: 120 | U2: - 输出网口：1 路千兆网口 - 最大带载像素：65 万像素 - 最大分辨率：2048×320 - 视频输入：HDMI×1 - 存储：8G 本地存储，U 盘脱机播放 - 控制接口：RS232，支持中控指令切换节目、调节亮度、黑屏 - 灰度等级：16bit，刷新率 1920‑3840Hz - 音频：3.5mm 音频输出 - 兼容模组：室内 P1.25‑P5，支持 1/8、1/16、1/32 扫 - 设备形态：盒式 130×85×30mm - 供电：AC220V - 保护功能：信号丢失黑屏、过热保护 | V2: 1.1 | AA2: 图文剪辑包装片 参数：1080P，30s-3min 工作量：素材整理、图文排版、基础转场、字幕配乐、简易配音剪辑，无实拍、无动画、无特效，1-2 人 1-3 天完成 | AB2: 5000 | AC2: 中控总控程序 功能：一键开关机、场景模式、信号切换、时序联动、灯光音响同步 专业参数：支持 TCP/IP、RS232、DMX512 协议；单系统支持≥100 个设备节点；指令响应时间≤100ms；兼容 Windows/Linux 系统。 | AD2: 10000
A3: 15.6 英寸 比例：16:9 分辨率：1920×1080 可视区域：345×194 mm 整机尺寸：370×220×25 mm 重量：1.2–1.5 kg 功率：15–20 W 亮度：400 cd/㎡ 对比度：1200:1 | B3: 1200 | C3: P1.25 COB/SMD显 基础规格 点间距：1.25mm 像素密度：640,000 dots/㎡ 模组尺寸：320×160mm（分辨率256×128） 封装技术：COB/SMD可选，支持前维护 箱体尺寸：640×480mm（标准拼接） 显示性能 亮度：800-1000 cd/㎡ 对比度：≥10,000:1 刷新率：3840Hz 灰度等级：16bit 色域：≥90% BT.2020 可视角度：水平160°/垂直150° 配套适配 电源配置：1㎡配置2台400W/5V电源 接收卡：1㎡配置0.25张标准接收卡 功耗：最大550W/㎡，平均200W/㎡ 线缆：RVV 3×4mm²主缆+3×2.5mm²分缆 | D3: 9600 | E3: 亮度≥8000 流明（ISO）、1080P 分辨率、≥10000:1 动态对比度，DLP 技术，可换镜头，支持 HDR10+/HLG、≥95% DCI-P3 色域；机身约 550×430×250mm、≤18kg，工程级加固机身，支持吊装；接口含 HDMI 、USBRJ45 千兆、RS232、VGA；具备 ±50° 梯校、360° 几何校正，兼容主流中控，IP54 防护、-15℃-50℃宽温、7×24 小时运行，支持远程监控 ；电源 AC 100-240V（50/60Hz），额定功耗≤450W、待机≤0.5W，带断电记忆。 | F3: 38500 | G3: 红外多点触摸； | H3: 300 | I3: OPS主机支持网络唤醒定时： | J3: 1200 | K3: CPU:I7八代\内存:8G\硬盘128G； | L3: 2500 | M3: 显卡：独显2GB； | N3: 800 | O3: 视频光传：LC单模接口，4K@60Hz 无压缩传输，单模 20km~80km，延迟 < 1ms，兼容 HDR/HDCP，支持双向音频、RS232/IR 回传 | P3: 1600 | Q3: 功放：四通道可选，8Ω 每路 600W，频响 20Hz-20kHz±0.3dB，失真≤0.03%，支持立体声 / 桥接模式，4 芯 Speakon 输出。 专业音响（4 只）：8Ω 额定功率 600W，频响 45Hz-20kHz，灵敏度 100dB，全频单元，支持 Speakon 接口0 | R3: 8900 | S3: 视音频跳线、网络跳线面板、固定结构、辅助配件、工具耗材 | T3: 180 | U3: - 输出网口：4 路千兆网口 - 最大带载像素：260 万像素 - 最大分辨率：4096×1024 - 视频输入：HDMI×2、DVI - 存储：8G 本地存储，U 盘脱机播放 - 控制接口：RS232，中控可调用节目、亮度调节、黑屏控制，支持逐点校正 - 灰度等级：16bit，刷新率 1920‑3840Hz - 音频：3.5mm 音频输出 - 兼容模组：室内 P1.25‑P5，支持 1/8、1/16、1/32 扫 - 设备形态：盒式，可选 1U 机架安装 - 供电：AC220V - 保护功能：信号丢失黑屏、过热保护 | AA3: 实拍素材剪辑 / MG 二维动画 参数：1080P-4K，1-5min 工作量：脚本梳理、现有影像精剪调色、播音配音、简易片头包装；MG 动画含扁平化图形设计、流程动画制作，3 人团队 5-10 天 | AB3: 30000 | AC3: 触摸屏互动查询程序 功能：图文浏览、视频点播、分类检索、触摸跳转 专业参数：基于 Unity/Unreal/Web 开发；支持 4K/8K 分辨率；触摸响应时间≤50ms；支持 10 点以上多点触控。 | AD3: 20000
A4: 19 英寸 比例：16:9 分辨率：1366×768 可视区域：421×237 mm 整机尺寸：435×255×30 mm 重量：2.0–2.5 kg 功率：20–25 W 亮度：450 cd/㎡ 对比度：1500:1 | B4: 1500 | C4: 基础规格 点间距：1.86mm 像素密度：288,000 dots/㎡ 模组尺寸：320×160mm（分辨率172×86） 封装技术：SMD 1515黑灯封装 箱体尺寸：640×480mm（标准拼接） 显示性能 亮度：800-1000 cd/㎡（支持低亮高灰） 对比度：≥5,000:1 刷新率：3840Hz 灰度等级：14-16bit 色域：≥85% NTSC 可视角度：水平160°/垂直150° 配套适配 电源配置：1㎡配置2台400W/5V电源 接收卡：1㎡配置0.25张接收卡 功耗：最大500W/㎡，平均180W/㎡ 线缆：RVV 3×4mm²主缆+3×2.5mm²分缆 | D4: 5500 | E4: 亮度≥10000 流明（ISO）、1080P 分辨率、≥10000:1 动态对比度，DLP 技术，可换镜头，支持 HDR10+/HLG、≥95% DCI-P3 色域；机身约 580×460×280mm、≤22kg，工程级加固机身，支持吊装；接口含 HDMI 2.1×3（4K/60Hz）、USB 3.0×2、RJ45 千兆 ×2、RS232×2、VGA×1；具备 ±50° 梯校、360° 旋转、边缘融合、几何校正，兼容主流中控，IP54 防护、-15℃-50℃宽温、7×24 小时运行，支持远程监控 / 批量升级 / 参数备份；电源 AC 100-240V（50/60Hz），额定功耗≤550W、待机≤0.5W，带断电记忆。 | F4: 58000 | G4: 超大红外触摸； | H4: 400 | I4: 小型机箱支持网络唤醒定时： | J4: 1800 | K4: CPU:I5十代以上;\内存:8G\硬盘128G； | L4: 2900 | M4: 显卡：独显8GB； | N4: 3200 | O4: USB2.0网传：USB3.0 转 RJ45，速率最高 5Gbps（实际约 3Gbps），六类线传 100m，兼容 USB2.0/1.1，支持 U 盘、相机等外设，延迟 10~50ms | P4: 800 | Q4: 功放：四通道，8Ω 每路 600W，频响 20Hz-20kHz，失真≤0.03%，支持桥接。 专业音响（4 只）：8Ω/600W，频响 45Hz-20kHz，灵敏度 100dB，Speakon 接口。 低音音响（1 只）：8Ω/800W，频响 35Hz-150Hz，灵敏度 102dB，双 12 英寸单元。 音频处理器：4 进 6 出，支持 24dB/oct 分频，带 EQ / 延时 / 限幅功能，适配全频 + 低音系统。 | R4: 21000 | T4: 0 | U4: - 输出网口：8 路千兆网口 - 最大带载像素：520 万像素 - 最大分辨率：8192×1536 - 视频输入：HDMI×3、DVI、DP - 存储：8G 本地存储，U 盘脱机播放 - 控制接口：RS232；支持多窗口漫游、双机冗余备份、设备状态网络回读、多屏分区独立画面、逐点校正，支持 4K 信号输入 - 灰度等级：16bit，刷新率 1920‑3840Hz - 音频：3.5mm 音频输出 - 兼容模组：室内 P1.25‑P5，支持 1/8、1/16、1/32 扫 - 设备形态：1U 机架式 - 供电：AC220V - 保护功能：信号丢失黑屏、过热保护 | AA4: 全流程实景宣传片 参数：4K 超清，2-6min 工作量：前期策划踩点、专业剧组拍摄、航拍取景、场景布光、电影级调色、高级特效包装、音效混音，5-8 人团队 15-30 天 | AB4: 80000 | AC4: 多通道弧幕 / 环幕同步播放程序 功能：画面融合、帧同步、多机拼接、无错位无缝联动 专业参数：支持 2-12 通道同步；同步精度≤1ms；支持 H.264/ProRes/DNxHD 编码；支持软硬件融合校正。 工作量：画面矫正、点位调试工作量大。 | AD4: 2000
A5: 27 英寸 比例：16:9 分辨率：1080P / 2K 可视区域：597×336 mm 整机尺寸：620×360×40 mm 重量：5.0–6.5 kg 功率：30–40 W 亮度：500 cd/㎡ 对比度：2000:1 | B5: 2200 | C5: 基础规格 点间距：2.5mm 像素密度：160,000 dots/㎡ 模组尺寸：320×160mm（分辨率128×64） 封装技术：SMD 2121 箱体尺寸：640×480mm（标准拼接） 显示性能 亮度：1000-1200 cd/㎡ 对比度：≥5,000:1 刷新率：3840Hz 灰度等级：14-16bit 色域：≥85% NTSC 可视角度：水平160°/垂直150° 配套适配 电源配置：1㎡配置2台400W/5V电源 接收卡：1㎡配置0.25张接收卡 功耗：最大450W/㎡，平均150W/㎡ 线缆：RVV 3×4mm²主缆+3×2.5mm²分缆 | D5: 3000 | E5: 亮度≥8000 流明（ISO）、3840*2160分辨率、≥10000:1 动态对比度，DLP 技术，可换镜头，支持 HDR10+/HLG、≥95% DCI-P3 色域；机身约 550×430×250mm、≤18.5g，工程级加固机身，支持吊装；接口含 HDMI 2.1×3（4K/60Hz）、USB 3.0×2、RJ45 千兆 ×2、RS232×2、VGA×1；具备 ±50° 梯校、360° 旋转、边缘融合、几何校正，兼容主流中控，IP54 防护、-15℃-50℃宽温、7×24 小时运行，支持远程监控 / 批量升级 / 参数备份；电源 AC 100-240V（50/60Hz），额定功耗≤450W、待机≤0.5W，带断电记忆。 | F5: 68000 | G5: 红外视觉识别系统：1080P/4K 分辨率、30-60fps 帧率，探测距离 0.5-20m，夜间无补光识别且抗强光干扰，输出目标坐标与轨迹；接口 RJ45/USB3.0，配套 SDK 开发包，支持 API/ROS 接口对接，可定制数据输出格式； | H5: 1800 | I5: A型工作站支持网络唤醒定时： | J5: 2000 | K5: CPU:I7十代以上;\内存:16G\硬盘256G； | L5: 4500 | M5: 显卡：独显16GB； | N5: 8000 | O5: USB3.0光传：LC/SC 单 / 多模接口，5Gbps 无损传输，多模传 500m~2km、单模 20km~100km，抗电磁干扰，支持多设备级联、即插即用。 | P5: 1800 | Q5: 超声波定向:指向 <15°(-20dB)；声压 78-83±3dB@2m；功率 15-20W；24V DC/3A；尺寸约 290×170×30mm | R5: 3900 | U5: - 输出网口：12 路千兆网口 - 最大带载像素：780 万像素 - 最大分辨率：16000×3840 - 视频输入：HDMI×4、DVI、DP - 存储：8G 本地存储，U 盘脱机播放 - 控制接口：RS232；支持多图层拼接、超大分辨率输出、接收卡在线升级、多屏幕独立输出、逐点校正、音频同步输出 - 灰度等级：16bit，刷新率 1920‑3840Hz - 音频：3.5mm 音频输出 - 兼容模组：室内 P1.25‑P5，支持 1/8、1/16、1/32 扫 - 设备形态：2U 机架式 - 供电：AC220V - 保护功能：信号丢失黑屏、过热保护 | AA5: 弧幕 / 环幕沉浸式专用影片 参数：超宽全景画幅、4K-8K，适配多通道融合 工作量：专属超广角镜头设计、画面畸变矫正、多通道画面缝合、逐帧校准拼接无缝衔接，额外增加画幅适配专项工序 | AB5: 100000 | AC5: 数字沙盘灯光联动程序 功能：沙盘灯光点位编程、影片与光影同步联动、区位动态演示 专业参数：支持 DMX512/Art-Net等 协议；单系统支持≥512 个控制点位；灯光与视频同步精度≤50ms | AD5: 25000
A6: 32 英寸 比例：16:9 分辨率：1080P 可视区域：708×398 mm 整机尺寸：730×420×50 mm 重量：7.0–9.0 kg 功率：40–60 W 亮度：500–600 cd/㎡ 对比度：2000:1 | B6: 2700 | C6: 基础规格 点间距：3.91mm 像素密度：65,478 dots/㎡ 模组尺寸：320×160mm（分辨率82×41） 封装技术：SMD 1921室内黑灯封装 模组厚度：≤18mm 显示性能 亮度：1200-1500 cd/㎡（室内舒适亮度，支持0-1500cd/㎡智能调节） 对比度：≥5,000:1 刷新率：≥3840Hz 灰度等级：14-16bit 防护等级：IP43（室内防尘） 可视角度：水平160°/垂直150° 配套适配 电源配置：1㎡配置1-2台400W/5V电源 接收卡：1㎡配置0.25-0.5张接收卡 功耗：最大600W/㎡，平均200W/㎡ 线缆：RVV 3×2.5mm²主缆+3×1.5mm²分缆 | D6: 2500 | E6: 亮度≥6500 流明，1080P 分辨率，100 万：1 动态对比度（开启），均匀性＞90%，兼容 16:9/4:3 等多宽高比；0.233:1 超短焦反射式镜头，120-180 英寸投影，±30° 梯校 + 四角矫正；输入接口含 VGA、DVI-I、HDMI、Ypbpr、3D VESA、HD-Baset、RJ45、USB 等，输出含 D-Sub、Audio、H/P OUT，控制端口 RS232/USB mini B/LAN；功耗 610W（待机≤0.5W），100-240V AC，10W 扬声器，高亮 2 万 / 节能 2.5 万小时寿命；尺寸 720×472×166mm，裸重 24.5KG，噪音 34-38DB-A；支持前投 / 背投、桌面 / 吊装、720° 任意安装，外观银 / 黑，工作温度 0-40℃，储藏 - 10-60℃。 | F6: 33500 | G6: 雷达识别交互系统：24GHz/77GHz 毫米波雷达，探测角度 ±60°，测距精度 ±0.1m，支持多目标跟踪，输出距离、速度、角度信息；通讯接口 RS485 / 以太网，提供二次开发接口，支持协议定制与多系统联动； | H6: 3800 | I6: B型工作站支持网络唤醒定时： | J6: 4000 | K6: CPU:I9十代以上;\内存:32G\硬盘1T； | L6: 6000 | M6: 显卡：独显24GB； | N6: 18000 | O6: 光纤HDMI:HDMI2.0/2.1 接口，带宽 18Gbps/48Gbps，对应 4K@60Hz/8K@60Hz，多模传 50m~300m，线径细、抗弯折，支持 HDR10+/eARC | P6: 100 | Q6: DSP 相控阵音柱：波束覆盖角：垂直 15°~60° 软件无级可调（0.1° 步进） 有效距离：2–12m 旁瓣 / 后方衰减：≥45dB，区域外低串音、低反射 频率响应：80Hz–18kHz 全频高保真 额定功率：240W 内置 D 类有源功放 供电：AC220V 支持：人体感应启停、AMX 中控协议、Dante 网络、多台分区组网（可选） 调试软件：PC 端3D 可视化声场建模，圈定听音区自动匹配波束，实时改角度 安装：约长：1200mm宽：110mm厚：75mm 重量：8.5kg壁挂 / 吊装; | R6: 7800 | AA6: 3D 三维建筑 / 古建漫游动画 参数：4K-8K 三维渲染影片，2-5min 工作量：场景三维建模、材质灯光渲染、建筑路径动画、结构可视化复原，建模 + 渲染周期长，10 人以上团队 30-60 天 | AB6: 150000 | AC6: 体感 / 手势互动程序/机械互动 功能：隔空控制、人体触发互动、答题交互、场景切换 专业参数：支持 Kinect/Leap Motion 等设备；手势识别准确率≥95%；动作响应时间≤150ms；基于 Unity/Unreal 引擎开发。 | AD6: 35000
A7: 43 英寸 比例：16:9 分辨率：1080P 可视区域：942×529 mm 整机尺寸：970×560×60 mm 重量：12–16 kg 功率：70–90 W 亮度：600 cd/㎡ 对比度：3000:1 | B7: 3200 | C7: 基础规格 点间距：5mm 像素密度：40,000 dots/㎡ 模组尺寸：320×160mm（分辨率64×32） 封装技术：SMD 2727户外高亮封装 模组厚度：≤20mm（带面罩） 显示性能 亮度：≥5000 cd/㎡（支持阳光直射下清晰可见） 对比度：≥4,000:1 刷新率：≥3840Hz 灰度等级：14-16bit 防护等级：IP65（正面完全防水，背面防尘） 可视角度：水平140°/垂直120° 配套适配 电源配置：1㎡配置1台400W/5V户外防水电源 接收卡：1㎡配置0.2张接收卡 功耗：最大800W/㎡，平均280W/㎡ 线缆：RVV 3×4mm²主缆+3×2.5mm²分缆（配套防水接头） | D7: 3000 | G7: 手势识别互动：支持 5-10 种核心手势，识别距离 0.3-3m，响应延迟＜100ms，兼容 Windows/Android，USB 即插即用；配套开发工具包，支持接口适配与手势自定义开发； | I7: 音视频播放器 | J7: 600 | K7: 八核 2.0G\4+32G\安卓 11\WiFi \网口 GPIO； | L7: 1200 | P7: 50 | AA7: CAVE 折幕 / 裸眼 3D 空间影片 参数：多面联动全景 8K 影片 工作量：三维空间镜头规划、多屏画面对位、立体景深制作、软硬件逐帧同步调试、空间画面无缝匹配 | AB7: 200000+ | AC7: CAVE 折幕 / 多面空间联动程序 功能：四面屏空间对位、三维景深同步、软硬件深度耦合 专业参数：支持 3-6 面屏幕联动；立体成像支持主动 / 被动式；分辨率支持单屏 4K；空间定位精度≤0.1°。 | AD7: 50000
A8: 50 英寸 比例：16:9 分辨率：1080P 可视区域：1107×623 mm 整机尺寸：1140×660×70 mm 重量：16–20 kg 功率：90–120 W 亮度：600 cd/㎡ 对比度：3000:1 | B8: 4500 | C8: 基础规格 点间距：10mm 像素密度：10,000 dots/㎡ 模组尺寸：320×160mm（分辨率32×16） 封装技术：SMD 3535户外高亮封装（或直插灯） 模组厚度：≤22mm（带面罩） 显示性能 亮度：≥6000 cd/㎡（强光环境下可视） 对比度：≥3,000:1 刷新率：≥1920Hz 灰度等级：12-14bit 防护等级：IP65（正面完全防水，背面防尘） 可视角度：水平140°/垂直120° 配套适配 电源配置：1㎡配置1台400W/5V户外防水电源 接收卡：1㎡配置0.1张接收卡 功耗：最大800W/㎡，平均300W/㎡ 线缆：RVV 3×4mm²主缆+3×2.5mm²分缆（配套防水接头） | D8: 1500 | G8: 体感识别套件：深度摄像头 + 算法模组，识别距离 0.5-5m、帧率 30fps，全身 15-22 骨骼点追踪、多人识别；接口 USB / 以太网，提供 SDK 二次开发支持，适配虚拟交互动作数据对接； | I8: IO\播控播放器 | J8: 700 | K8: 四核 2.0G\2+16G\安卓 9\网口； | L8: 800 | AC8: 智慧展馆运维管理程序 功能：客流统计、设备巡检、故障报警、运行日志、远程控制 专业参数：数据采集频率≤5s；支持 Modbus/OpcUa 协议；提供 API 接口与第三方系统对接；支持移动端管理。 | AD8: 50000
A9: 55 英寸 比例：16:9 分辨率：2K 可视区域：1218×685 mm 整机尺寸：1250×720×70 mm 重量：18–24 kg 功率：120–150 W 亮度：700 cd/㎡ 对比度：3000:1 | B9: 5000 | G9: IO\感应\射频遥控输入，UDP\TCP\485,继电器输出控制器 | H9: 500 | I9: 可视中控播放器 | J9: 1200
A10: 65 英寸 比例：16:9 分辨率：4K 可视区域：1457×819 mm 整机尺寸：1490×855×80 mm 重量：25–32 kg 功率：150–180 W 亮度：700–800 cd/㎡ 对比度：4000:1 | B10: 4000 | I10: 视频融合播放器 | J10: 1800
A11: 75 英寸 比例：16:9 分辨率：4K 可视区域：1670×939 mm 整机尺寸：1710×980×85 mm 重量：35–45 kg 功率：180–220 W 亮度：800 cd/㎡ 对比度：4000:1 | B11: 9500 | O11: 网传光传可加：USB2.0\串口\红外（单功能50元）
A12: 86 英寸 比例：16:9 分辨率：4K 可视区域：1890×1060 mm 整机尺寸：1930×1100×90 mm 重量：50–65 kg 功率：250–350 W 亮度：800–1000 cd/㎡ 对比度：5000:1 | B12: 15000 | M12: (4K)P620 显存：2GB GDDR5，128bit 单口最高：5120×2880 @ 60Hz（DP 1.4） 多口带载：4 屏，每屏 4096×2160@60Hz（4×mDP） 功耗 / 尺寸：40W，半高单槽，约 140 × 68 mm | N12: 1000
A13: 98 英寸 比例：16:9 分辨率：4K 可视区域：2170×1220 mm 整机尺寸：2210×1260×100 mm 重量：70–90 kg 功率：350–450 W 亮度：1000 cd/㎡ 对比度：5000:1 | B13: 20000 | M13: (8K)RTX 3050 显存：8GB GDDR6 单口最高：8K@60Hz（DP 1.4） 多口带载：4 屏（3DP+1HDMI），4×4K@60Hz 功耗：130W | N13: 1800
A14: 120 英寸 比例：16:9 分辨率：4K 可视区域：2656×1494 mm 整机尺寸：2700×1540×120 mm 重量：130–180 kg 功率：500–800 W 亮度：1200–1500 cd/㎡ 对比度：10000:1； | B14: 45000 | M14: RTX 3060 12G 显存：12GB GDDR6 单口最高：8K@60Hz 多口带载：4 屏，4×4K@60Hz，支持拼接墙 功耗：170W | N14: 2400
A15: 46寸-3.5mm型一、产品规格：尺寸1022×577×80（HWD，mm） 重量：11kg | B15: 5000 | M15: RTX A4000 16G 显存：16GB GDDR6（ECC） 单口最高：8K@60Hz（DP 1.4a）NVIDIA 多口带载：4 屏，4×4K@120Hz / 2×8K@60Hz 功耗 / 尺寸：140W，单槽 | N15: 6800
A16: 46寸-0.88mm型一、产品规格：尺寸1022×577×80（HWD，mm） 重量：11kg | B16: 6000 | M16: RTX A5000 显存：24GB GDDR6 ECC 单口分辨率：8K@60Hz 多口带载：4×DP，4 屏 8K@60Hz，支持 Mosaic 拼接 功耗：230W | N16: 12000+
A17: 55寸-3.5mm型一、产品规格：尺寸1214×685×80（HWD，mm） 重量：13kg | B17: 6500 | M17: RTX 5090 32GB 显存：32GB GDDR7（512bit，1792GB/s）NVIDIA 单口最高：8K@120Hz（DP 2.1b / HDMI 2.1b） 多口带载：4 屏（3×DP2.1 + 1×HDMI2.1），支持 4×8K@60Hz / 2×8K@120Hz， 功耗：575W | N17: 20000+
A18: 55寸-0.88mm型一、产品规格：尺寸1214×685×80（HWD，mm） 重量：13kg | B18: 7500 | M18: NVIDIA H100 显存：80GB HBM3（3.35TB/s 带宽，ECC） AI 算力：FP16≈989 TFLOPS，FP8≈2000 TFLOPS 适用：175B + 超大模型预训练、超算级 AI 任务 功耗：700W（SXM5 版）/400W（PCIe 版） | N18: 300000+
A19: 15.7圆形屏规格：对角线长度 39.88 厘米，分辨率为 960×960（PPI= 86.5），亮度 700cd/m²，对比度 1000:1； | B19: 9800
A20: 23.6圆形屏规格：对角线长度 600厘米，分辨率为 1280×1280（PPI= 115.3），亮度 700cd/m²，对比度 1000:1； | B20: 14500
A21: OLED技术：尺寸1221.5×699.35mm；，画面比例16:9；亮度150/400nit（APL 100%/25%）；透光率38%；色域108%；水平垂直可视角度178°×178°；色深10bit(R)，10.7亿色；响应时间1ms(G to G)，8ms(MPRT)；刷新率120Hz； | B21: 48000

Sheet 使用方法
A1: 使用前请仔细阅读操作流程
A2: 1、使用前请手动完善好数据库(注意不能改变第一行黄色底文字内容顺序)，维护好销售价格。
A3: 2、表格设定自动计算公式，填写型号和数量即可自动计算结果。（数据库需要有对应的产品数据才能查询到价格）
A4: 3、利润和平台服务费可以自行修改比率。按实际填写。
A5: 4、使用时修改以下位置即可计算价格，办公软件推荐wps。
A6: 5、为了防止误删公式，已经设置公式保护，解锁密码为123

Sheet 网络
A1: 设备类型 | B1: 型号 | C1: 核心参数 | D1: 单台价位（元）
A2: 展项，带机量≤10
A3: 无线路由 | B3: AR180pro | C3: 无线：Wi-Fi 7，双频并发 3600Mbps 端口：2×2.5GE，4×GE，支持多 WAN 带机量：150 台 天线：4 根外置高增益天线 功耗：13.5W 功能：VPN、上网行为管理、Mesh | D3: 650
A4: 路由交换一体机 | B4: 华为S380-S8P2T | C4: 端口：2×GE WAN + 8×GE LAN（全口 PoE+，124W） 性能：带机 10+ 台、管理 8AP（免费）、交换 16Gbps、包转发 500/420Kpps、出口 2Gbps | D4: 1299
A5: AP | B5: AirEngine5761-11 | C5: 端口：1×GE电口 性能：Wi-Fi6双频，2.4GHz+5GHz，空口速率1.775Gbps，推荐并发用户36人、无缝漫游 供电：支持802.3at/af PoE供电、DC12V电源输入，最大功耗14.2W | D5: 850
A6: 8口交换机 | B6: S110-8T | C6: 端口：8×GE 电口，无上行口 性能：交换 16Gbps、包转发 11.9Mpps、MAC 2K 供电：DC12V，功耗≈7W | D6: 135
A7: 8口交换机（网管） | B7: S210-8T | C7: 端口：8×GE 电口 性能：交换 16Gbps、包转发 12Mpps、MAC 2K 管理：Web/APP/SSH，VLAN / 端口隔离 / QoS 定位：轻网管接入 | D7: 400
A8: 24口交换机 | B8: S110-24TR | C8: 端口：24×GE 电口，机架式 性能：交换 48Gbps、包转发 35.7Mpps、MAC 8K 供电：AC 100–240V，无 PoE，功耗≈8W | D8: 620
A9: 24口POE交换机 | B9: S1730S-L24PR-A | C9: 端口：24×GE（PoE+），机架式 性能：交换 48Gbps、包转发 35.7Mpps、MAC 8K PoE：总功率 191W（802.3af/at） | D9: 1500
A10: 24口POE交换机（网管） | B10: S5735S-L24P4S-A2 | C10: 端口：24×GE（PoE+）+4×GE SFP 上行 性能：交换 48Gbps、包转发 36Mpps、MAC 8K PoE：总功率 370W（满供 24 口 af/16 口 at） 管理：Web/APP/ 云管理，三层基础功能 | D10: 2500
A12: 展厅，带机量≤50
A13: 核心交换机-24口电口 | B13: 华为S5735S-L24T4S-A | C13: 24个千兆电口，4个千兆SFP上行口，交换容量336Gbps，包转发率42Mpps，二层网管 | D13: 3200
A14: 核心交换机-24口光口 | B14: 华为S5735S-L24S4S-A | C14: 24个千兆光口，4个千兆SFP上行口，交换容量336Gbps，包转发率42Mpps，二层网管 | D14: 3500
A15: 核心交换机-48口光口 | B15: 华为S5735S-L48S4S-A | C15: 48个千兆光口，4个千兆SFP上行口，交换容量336Gbps，包转发率42Mpps，二层网管 | D15: 5800
A16: 24口POE交换机 | B16: 华为S1730S-L24P4S-A | C16: 24个千兆POE电口，4个千兆SFP上行口，POE总功率180W，即插即用，二层非网管，适合超小型办公场景 | D16: 2800
A17: 24口POE交换机 | B17: 华为S1730S-S24P4S-A1 | C17: 24个千兆POE+电口，4个千兆SFP上行口，POE总功率380W，即插即用，二层网管 | D17: 4200
A18: 24口常规交换机 | B18: 华为S1730S-S24T4S-A1 | C18: 24个千兆电口，4个千兆SFP上行口，交换容量336Gbps，包转发率42Mpps，即插即用 | D18: 1800
A19: 48口常规交换机 | B19: 华为S1730S-S48T4S-A1 | C19: 48个千兆电口，4个千兆SFP上行口，交换容量336Gbps，包转发率42Mpps，即插即用 | D19: 3200
A20: AC控制器 | B20: 9700S-S | C20: 端口：10×GE 电口 + 2×10GE SFP + 光口 性能：最大可管理 128 个 AP，转发能力 10Gbps，支持 10Gbps 数据转发 功能：集成千兆交换机功能，支持无线漫游、安全认证、本地 / 隧道转发双模式 供电：AC/DC 电源适配器，功耗 21W | D20: 1500
B21: AC6508 | C21: 端口：10×GE 电口 + 2×10GE SFP + 光口 性能：最大可管理 512 个 AP，支持 4096 个并发无线用户，转发能力 10Gbps 功能：支持直接 / 隧道转发模式，基于用户 / 角色的权限控制，丰富的运维管理方式 供电：AC/DC 电源适配器，功耗 25.06W | D21: 6600
A22: 授权 | B22: L-ACSSAP-16AP | D22: 2800
B23: L-ACSSAP-32AP | D23: 4500
B24: L-ACSSAP-64AP | D24: 9500
B25: L-ACSSAP-128AP | D25: 18000
A26: 无线AP | B26: AirEngine5762S-22 | C26: WiFi6双频5400M，吸顶式，推荐带机量50+，覆盖半径30m，支持PoE+供电，智能天线，无缝漫游 | D26: 1550
A27: 无线AP-高密 | B27: AirEngine6776-58TI | C27: Wi-Fi 7 三频 12.2G，吸顶式，推荐带机量 200+，覆盖半径 25m，支持 PoE++ 供电，高密场景优化，智能天线，无缝漫游 | D27: 3500
A28: 千兆单模 | B28: FP-GE-LX | C28: 1310nm,10km,LC | D28: 180
A29: 万兆单模 | B29: SFP+-10G | C29: 1310nm,10km,LC | D29: 260
A30: 千兆电口 | B30: SFP-1000BaseT | C30: 100m,RJ45 | D30: 350
A31: 200设备（展馆，带机量≤200）
A32: 路由器 | B32: AR611E-S | C32: 多WAN口设计，带机量200，内置AC管理功能，支持VPN/防火墙/安全防护 | D32: 1800
A33: 核心交换机-24口电口 | B33: 华为S5735-H24T4XC | C33: 24个千兆电口，4个万兆SFP+上行口，交换容量520Gbps，包转发率132Mpps，三层网管 | D33: 5500
A34: 核心交换机-24口光口 | B34: 华为S5735-H24S4XC | C34: 24个千兆光口，4个万兆SFP+上行口，交换容量520Gbps，包转发率132Mpps，三层网管 | D34: 5800
A35: 核心交换机-48口光口 | B35: 华为S5735-H48S4XC | C35: 48个千兆光口，4个万兆SFP+上行口，交换容量520Gbps，包转发率132Mpps，三层网管 | D35: 9800
A36: 24口POE交换机 | B36: 华为S5735-L24P4XE-A-V2 | C36: 24个千兆POE+电口，4个万兆SFP+上行口，POE总功率370W，三层网管，支持VLAN/PoE+ | D36: 6500
A37: 24口交换机 | B37: 华为S5735-L24T4XE-A-V2 | C37: 24个千兆电口，4个万兆SFP+上行口，交换容量520Gbps，包转发率132Mpps，三层网管 | D37: 3200
A38: 48口交换机 | B38: 华为S5735-L48T4XE-A-V2 | C38: 48个千兆电口，4个万兆SFP+上行口，交换容量520Gbps，包转发率207Mpps，三层网管 | D38: 5200
A39: 园区，带机量≤800；堆叠
A40: 路由器 | B40: 华为AR6140-S | C40: 5个GE RJ45口+4个GE SFP口，带机量1200，支持多WAN/SD-WAN/防火墙/VPN | D40: 9100
A41: 核心交换机-24口电口 | B41: 华为S5732-H24UM2CC | C41: 24个2.5G电口（可升级至10G），4个25GE SFP28+2个40GE QSFP+上行口，交换容量2.4Tbps，包转发率960Mpps，三层核心 | D41: 12000
...
